Workbook

Sheet README!
C1: Rekord
C2: This workbook is used to prepare and export student data for Grade 4 SF10-ES generation. Fill in the Class Info and Grades sheets, export the Export sheet as a CSV, and upload it to Rekord to batch-generate ready-to-print PDFs for all your students.
C3: Here's a quick guide to get you started with this template:
C4: Step 1 — Fill in Class Info
C5: Head over to the "Class Info" sheet and start filling in your students' info, one student per row. You can have up to 100 students.
C6: Go to Class Info Sheet →
C7: Step 2 — Enter Grades
C8: Switch to the "Grades" sheet and fill in each student's quarterly grades (Q1–Q4) per subject. Don't worry about the LRN and name columns since those are pulled automatically from Class Info. The Final Rating and General Average are also computed for you, so no need to worry about those.
C9: Go to Grades Sheet →
C10: Step 3 — Export
C11: Go to "Export" sheet (very important), then go to File → Export → Change File Type → CSV (Comma delimited) (*.csv) → Save As. Excel might warn you that only the current sheet will be saved, that's totally fine, just click OK.
C12: #VALUE!
C13: Go to Export Sheet →
C14: Step 4 — Upload to Rekord
C15: Go to Rekord, upload the CSV you just saved, fill in the required fields, and hit Process. In a few seconds, you'll have a ZIP file with a PDF for every student. Donezo! 🎉
C16: Go to Rekord →
C17: If you wish to edit this workbook although strongly not recommended, the password is rekord4321.
C19: #VALUE! | D19: #VALUE!

Sheet Class Info
A1: LEARNER'S PERSONAL INFORMATION | H1: ELIGIBILITY FOR ELEMENTARY SCHOOL ENROLLMENT
A2: LRN | B2: Last Name | C2: First Name | D2: Middle Name | E2: Extn. | F2: Birthdate (mm/dd/yy) | G2: Sex | H2: Credential Presented for Grade 1 | I2: Name of School | J2: School Address | K2: PEPT Passer Rating | L2: Date of Examination | M2: Name and Address of Testing Center | N2: Other Credentials Presented | O2: Remark

Sheet Grades
A1: LRN | B1: Last Name | C1: First Name | D1: Quarter 1 | P1: Quarter 2 | AB1: Quarter 3 | AN1: Quarter 4 | AZ1: Final
D2: Fil | E2: Eng | F2: Math | G2: Sci | H2: GMRC | I2: AP | J2: EPP | K2: MAPEH | L2: Music and Arts | M2: PE and Health | N2: Arb | O2: Islam | P2: Fil | Q2: Eng | R2: Math | S2: Sci | T2: GMRC | U2: AP | V2: EPP | W2: MAPEH | X2: Music and Arts | Y2: PE and Health | Z2: Arb | AA2: Islam | AB2: Fil | AC2: Eng | AD2: Math | AE2: Sci | AF2: GMRC | AG2: AP | AH2: EPP | AI2: MAPEH | AJ2: Music and Arts | AK2: PE and Health | AL2: Arb | AM2: Islam | AN2: Fil | AO2: Eng | AP2: Math | AQ2: Sci | AR2: GMRC | AS2: AP | AT2: EPP | AU2: MAPEH | AV2: Music and Arts | AW2: PE and Health | AX2: Arb | AY2: Islam | AZ2: Fil | BA2: Eng | BB2: Math | BC2: Sci | BD2: GMRC | BE2: AP | BF2: EPP | BG2: MAPEH | BH2: Music and Arts | BI2: PE and Health | BJ2: Arb | BK2: Islam | BL2: General Average
A3: =IF('Class Info'!A3="","", 'Class Info'!A3) | B3: =IF('Class Info'!B3="","", 'Class Info'!B3) | C3: =IF('Class Info'!C3="","", 'Class Info'!C3) | AZ3: =IF(COUNT(D3,P3,AB3,AN3)=0, "", ROUND(AVERAGE(D3,P3,AB3,AN3), 0)) | BA3: =IF(COUNT(E3,Q3,AC3,AO3)=0, "", ROUND(AVERAGE(E3,Q3,AC3,AO3), 0)) | BB3: =IF(COUNT(F3,R3,AD3,AP3)=0, "", ROUND(AVERAGE(F3,R3,AD3,AP3), 0)) | BC3: =IF(COUNT(G3,S3,AE3,AQ3)=0, "", ROUND(AVERAGE(G3,S3,AE3,AQ3), 0)) | BD3: =IF(COUNT(H3,T3,AF3,AR3)=0, "", ROUND(AVERAGE(H3,T3,AF3,AR3), 0)) | BE3: =IF(COUNT(I3,U3,AG3,AS3)=0, "", ROUND(AVERAGE(I3,U3,AG3,AS3), 0)) | BF3: =IF(COUNT(J3,V3,AH3,AT3)=0, "", ROUND(AVERAGE(J3,V3,AH3,AT3), 0)) | BG3: =IF(COUNT(K3,W3,AI3,AU3)=0, "", ROUND(AVERAGE(K3,W3,AI3,AU3), 0)) | ... BK3: =IF(COUNT(O3,AA3,AM3,AY3)=0, "", ROUND(AVERAGE(O3,AA3,AM3,AY3), 0)) | BL3: =IF(COUNT(AZ3:BG3,BJ3:BK3)=0, "", ROUND(AVERAGE(AZ3:BG3,BJ3:BK3), 0))
A4: =IF('Class Info'!A4="","", 'Class Info'!A4) | B4: =IF('Class Info'!B4="","", 'Class Info'!B4) | C4: =IF('Class Info'!C4="","", 'Class Info'!C4) | AZ4: =IF(COUNT(D4,P4,AB4,AN4)=0, "", ROUND(AVERAGE(D4,P4,AB4,AN4), 0)) | BA4: =IF(COUNT(E4,Q4,AC4,AO4)=0, "", ROUND(AVERAGE(E4,Q4,AC4,AO4), 0)) | BB4: =IF(COUNT(F4,R4,AD4,AP4)=0, "", ROUND(AVERAGE(F4,R4,AD4,AP4), 0)) | BC4: =IF(COUNT(G4,S4,AE4,AQ4)=0, "", ROUND(AVERAGE(G4,S4,AE4,AQ4), 0)) | BD4: =IF(COUNT(H4,T4,AF4,AR4)=0, "", ROUND(AVERAGE(H4,T4,AF4,AR4), 0)) | BE4: =IF(COUNT(I4,U4,AG4,AS4)=0, "", ROUND(AVERAGE(I4,U4,AG4,AS4), 0)) | BF4: =IF(COUNT(J4,V4,AH4,AT4)=0, "", ROUND(AVERAGE(J4,V4,AH4,AT4), 0)) | BG4: =IF(COUNT(K4,W4,AI4,AU4)=0, "", ROUND(AVERAGE(K4,W4,AI4,AU4), 0)) | ... BK4: =IF(COUNT(O4,AA4,AM4,AY4)=0, "", ROUND(AVERAGE(O4,AA4,AM4,AY4), 0)) | BL4: =IF(COUNT(AZ4:BG4,BJ4:BK4)=0, "", ROUND(AVERAGE(AZ4:BG4,BJ4:BK4), 0))
A5: =IF('Class Info'!A5="","", 'Class Info'!A5) | B5: =IF('Class Info'!B5="","", 'Class Info'!B5) | C5: =IF('Class Info'!C5="","", 'Class Info'!C5) | AZ5: =IF(COUNT(D5,P5,AB5,AN5)=0, "", ROUND(AVERAGE(D5,P5,AB5,AN5), 0)) | BA5: =IF(COUNT(E5,Q5,AC5,AO5)=0, "", ROUND(AVERAGE(E5,Q5,AC5,AO5), 0)) | BB5: =IF(COUNT(F5,R5,AD5,AP5)=0, "", ROUND(AVERAGE(F5,R5,AD5,AP5), 0)) | BC5: =IF(COUNT(G5,S5,AE5,AQ5)=0, "", ROUND(AVERAGE(G5,S5,AE5,AQ5), 0)) | BD5: =IF(COUNT(H5,T5,AF5,AR5)=0, "", ROUND(AVERAGE(H5,T5,AF5,AR5), 0)) | BE5: =IF(COUNT(I5,U5,AG5,AS5)=0, "", ROUND(AVERAGE(I5,U5,AG5,AS5), 0)) | BF5: =IF(COUNT(J5,V5,AH5,AT5)=0, "", ROUND(AVERAGE(J5,V5,AH5,AT5), 0)) | BG5: =IF(COUNT(K5,W5,AI5,AU5)=0, "", ROUND(AVERAGE(K5,W5,AI5,AU5), 0)) | ... BK5: =IF(COUNT(O5,AA5,AM5,AY5)=0, "", ROUND(AVERAGE(O5,AA5,AM5,AY5), 0)) | BL5: =IF(COUNT(AZ5:BG5,BJ5:BK5)=0, "", ROUND(AVERAGE(AZ5:BG5,BJ5:BK5), 0))
A6: =IF('Class Info'!A6="","", 'Class Info'!A6) | B6: =IF('Class Info'!B6="","", 'Class Info'!B6) | C6: =IF('Class Info'!C6="","", 'Class Info'!C6) | AZ6: =IF(COUNT(D6,P6,AB6,AN6)=0, "", ROUND(AVERAGE(D6,P6,AB6,AN6), 0)) | BA6: =IF(COUNT(E6,Q6,AC6,AO6)=0, "", ROUND(AVERAGE(E6,Q6,AC6,AO6), 0)) | BB6: =IF(COUNT(F6,R6,AD6,AP6)=0, "", ROUND(AVERAGE(F6,R6,AD6,AP6), 0)) | BC6: =IF(COUNT(G6,S6,AE6,AQ6)=0, "", ROUND(AVERAGE(G6,S6,AE6,AQ6), 0)) | BD6: =IF(COUNT(H6,T6,AF6,AR6)=0, "", ROUND(AVERAGE(H6,T6,AF6,AR6), 0)) | BE6: =IF(COUNT(I6,U6,AG6,AS6)=0, "", ROUND(AVERAGE(I6,U6,AG6,AS6), 0)) | BF6: =IF(COUNT(J6,V6,AH6,AT6)=0, "", ROUND(AVERAGE(J6,V6,AH6,AT6), 0)) | BG6: =IF(COUNT(K6,W6,AI6,AU6)=0, "", ROUND(AVERAGE(K6,W6,AI6,AU6), 0)) | ... BK6: =IF(COUNT(O6,AA6,AM6,AY6)=0, "", ROUND(AVERAGE(O6,AA6,AM6,AY6), 0)) | BL6: =IF(COUNT(AZ6:BG6,BJ6:BK6)=0, "", ROUND(AVERAGE(AZ6:BG6,BJ6:BK6), 0))
A7: =IF('Class Info'!A7="","", 'Class Info'!A7) | B7: =IF('Class Info'!B7="","", 'Class Info'!B7) | C7: =IF('Class Info'!C7="","", 'Class Info'!C7) | AZ7: =IF(COUNT(D7,P7,AB7,AN7)=0, "", ROUND(AVERAGE(D7,P7,AB7,AN7), 0)) | BA7: =IF(COUNT(E7,Q7,AC7,AO7)=0, "", ROUND(AVERAGE(E7,Q7,AC7,AO7), 0)) | BB7: =IF(COUNT(F7,R7,AD7,AP7)=0, "", ROUND(AVERAGE(F7,R7,AD7,AP7), 0)) | BC7: =IF(COUNT(G7,S7,AE7,AQ7)=0, "", ROUND(AVERAGE(G7,S7,AE7,AQ7), 0)) | BD7: =IF(COUNT(H7,T7,AF7,AR7)=0, "", ROUND(AVERAGE(H7,T7,AF7,AR7), 0)) | BE7: =IF(COUNT(I7,U7,AG7,AS7)=0, "", ROUND(AVERAGE(I7,U7,AG7,AS7), 0)) | BF7: =IF(COUNT(J7,V7,AH7,AT7)=0, "", ROUND(AVERAGE(J7,V7,AH7,AT7), 0)) | BG7: =IF(COUNT(K7,W7,AI7,AU7)=0, "", ROUND(AVERAGE(K7,W7,AI7,AU7), 0)) | ... BK7: =IF(COUNT(O7,AA7,AM7,AY7)=0, "", ROUND(AVERAGE(O7,AA7,AM7,AY7), 0)) | BL7: =IF(COUNT(AZ7:BG7,BJ7:BK7)=0, "", ROUND(AVERAGE(AZ7:BG7,BJ7:BK7), 0))
A8: =IF('Class Info'!A8="","", 'Class Info'!A8) | B8: =IF('Class Info'!B8="","", 'Class Info'!B8) | C8: =IF('Class Info'!C8="","", 'Class Info'!C8) | AZ8: =IF(COUNT(D8,P8,AB8,AN8)=0, "", ROUND(AVERAGE(D8,P8,AB8,AN8), 0)) | BA8: =IF(COUNT(E8,Q8,AC8,AO8)=0, "", ROUND(AVERAGE(E8,Q8,AC8,AO8), 0)) | BB8: =IF(COUNT(F8,R8,AD8,AP8)=0, "", ROUND(AVERAGE(F8,R8,AD8,AP8), 0)) | BC8: =IF(COUNT(G8,S8,AE8,AQ8)=0, "", ROUND(AVERAGE(G8,S8,AE8,AQ8), 0)) | BD8: =IF(COUNT(H8,T8,AF8,AR8)=0, "", ROUND(AVERAGE(H8,T8,AF8,AR8), 0)) | BE8: =IF(COUNT(I8,U8,AG8,AS8)=0, "", ROUND(AVERAGE(I8,U8,AG8,AS8), 0)) | BF8: =IF(COUNT(J8,V8,AH8,AT8)=0, "", ROUND(AVERAGE(J8,V8,AH8,AT8), 0)) | BG8: =IF(COUNT(K8,W8,AI8,AU8)=0, "", ROUND(AVERAGE(K8,W8,AI8,AU8), 0)) | ... BK8: =IF(COUNT(O8,AA8,AM8,AY8)=0, "", ROUND(AVERAGE(O8,AA8,AM8,AY8), 0)) | BL8: =IF(COUNT(AZ8:BG8,BJ8:BK8)=0, "", ROUND(AVERAGE(AZ8:BG8,BJ8:BK8), 0))
A9: =IF('Class Info'!A9="","", 'Class Info'!A9) | B9: =IF('Class Info'!B9="","", 'Class Info'!B9) | C9: =IF('Class Info'!C9="","", 'Class Info'!C9) | AZ9: =IF(COUNT(D9,P9,AB9,AN9)=0, "", ROUND(AVERAGE(D9,P9,AB9,AN9), 0)) | BA9: =IF(COUNT(E9,Q9,AC9,AO9)=0, "", ROUND(AVERAGE(E9,Q9,AC9,AO9), 0)) | BB9: =IF(COUNT(F9,R9,AD9,AP9)=0, "", ROUND(AVERAGE(F9,R9,AD9,AP9), 0)) | BC9: =IF(COUNT(G9,S9,AE9,AQ9)=0, "", ROUND(AVERAGE(G9,S9,AE9,AQ9), 0)) | BD9: =IF(COUNT(H9,T9,AF9,AR9)=0, "", ROUND(AVERAGE(H9,T9,AF9,AR9), 0)) | BE9: =IF(COUNT(I9,U9,AG9,AS9)=0, "", ROUND(AVERAGE(I9,U9,AG9,AS9), 0)) | BF9: =IF(COUNT(J9,V9,AH9,AT9)=0, "", ROUND(AVERAGE(J9,V9,AH9,AT9), 0)) | BG9: =IF(COUNT(K9,W9,AI9,AU9)=0, "", ROUND(AVERAGE(K9,W9,AI9,AU9), 0)) | ... BK9: =IF(COUNT(O9,AA9,AM9,AY9)=0, "", ROUND(AVERAGE(O9,AA9,AM9,AY9), 0)) | BL9: =IF(COUNT(AZ9:BG9,BJ9:BK9)=0, "", ROUND(AVERAGE(AZ9:BG9,BJ9:BK9), 0))
A10: =IF('Class Info'!A10="","", 'Class Info'!A10) | B10: =IF('Class Info'!B10="","", 'Class Info'!B10) | C10: =IF('Class Info'!C10="","", 'Class Info'!C10) | AZ10: =IF(COUNT(D10,P10,AB10,AN10)=0, "", ROUND(AVERAGE(D10,P10,AB10,AN10), 0)) | BA10: =IF(COUNT(E10,Q10,AC10,AO10)=0, "", ROUND(AVERAGE(E10,Q10,AC10,AO10), 0)) | BB10: =IF(COUNT(F10,R10,AD10,AP10)=0, "", ROUND(AVERAGE(F10,R10,AD10,AP10), 0)) | BC10: =IF(COUNT(G10,S10,AE10,AQ10)=0, "", ROUND(AVERAGE(G10,S10,AE10,AQ10), 0)) | BD10: =IF(COUNT(H10,T10,AF10,AR10)=0, "", ROUND(AVERAGE(H10,T10,AF10,AR10), 0)) | BE10: =IF(COUNT(I10,U10,AG10,AS10)=0, "", ROUND(AVERAGE(I10,U10,AG10,AS10), 0)) | BF10: =IF(COUNT(J10,V10,AH10,AT10)=0, "", ROUND(AVERAGE(J10,V10,AH10,AT10), 0)) | BG10: =IF(COUNT(K10,W10,AI10,AU10)=0, "", ROUND(AVERAGE(K10,W10,AI10,AU10), 0)) | ... BK10: =IF(COUNT(O10,AA10,AM10,AY10)=0, "", ROUND(AVERAGE(O10,AA10,AM10,AY10), 0)) | BL10: =IF(COUNT(AZ10:BG10,BJ10:BK10)=0, "", ROUND(AVERAGE(AZ10:BG10,BJ10:BK10), 0))
A11: =IF('Class Info'!A11="","", 'Class Info'!A11) | B11: =IF('Class Info'!B11="","", 'Class Info'!B11) | C11: =IF('Class Info'!C11="","", 'Class Info'!C11) | AZ11: =IF(COUNT(D11,P11,AB11,AN11)=0, "", ROUND(AVERAGE(D11,P11,AB11,AN11), 0)) | BA11: =IF(COUNT(E11,Q11,AC11,AO11)=0, "", ROUND(AVERAGE(E11,Q11,AC11,AO11), 0)) | BB11: =IF(COUNT(F11,R11,AD11,AP11)=0, "", ROUND(AVERAGE(F11,R11,AD11,AP11), 0)) | BC11: =IF(COUNT(G11,S11,AE11,AQ11)=0, "", ROUND(AVERAGE(G11,S11,AE11,AQ11), 0)) | BD11: =IF(COUNT(H11,T11,AF11,AR11)=0, "", ROUND(AVERAGE(H11,T11,AF11,AR11), 0)) | BE11: =IF(COUNT(I11,U11,AG11,AS11)=0, "", ROUND(AVERAGE(I11,U11,AG11,AS11), 0)) | BF11: =IF(COUNT(J11,V11,AH11,AT11)=0, "", ROUND(AVERAGE(J11,V11,AH11,AT11), 0)) | BG11: =IF(COUNT(K11,W11,AI11,AU11)=0, "", ROUND(AVERAGE(K11,W11,AI11,AU11), 0)) | ... BK11: =IF(COUNT(O11,AA11,AM11,AY11)=0, "", ROUND(AVERAGE(O11,AA11,AM11,AY11), 0)) | BL11: =IF(COUNT(AZ11:BG11,BJ11:BK11)=0, "", ROUND(AVERAGE(AZ11:BG11,BJ11:BK11), 0))
A12: =IF('Class Info'!A12="","", 'Class Info'!A12) | B12: =IF('Class Info'!B12="","", 'Class Info'!B12) | C12: =IF('Class Info'!C12="","", 'Class Info'!C12) | AZ12: =IF(COUNT(D12,P12,AB12,AN12)=0, "", ROUND(AVERAGE(D12,P12,AB12,AN12), 0)) | BA12: =IF(COUNT(E12,Q12,AC12,AO12)=0, "", ROUND(AVERAGE(E12,Q12,AC12,AO12), 0)) | BB12: =IF(COUNT(F12,R12,AD12,AP12)=0, "", ROUND(AVERAGE(F12,R12,AD12,AP12), 0)) | BC12: =IF(COUNT(G12,S12,AE12,AQ12)=0, "", ROUND(AVERAGE(G12,S12,AE12,AQ12), 0)) | BD12: =IF(COUNT(H12,T12,AF12,AR12)=0, "", ROUND(AVERAGE(H12,T12,AF12,AR12), 0)) | BE12: =IF(COUNT(I12,U12,AG12,AS12)=0, "", ROUND(AVERAGE(I12,U12,AG12,AS12), 0)) | BF12: =IF(COUNT(J12,V12,AH12,AT12)=0, "", ROUND(AVERAGE(J12,V12,AH12,AT12), 0)) | BG12: =IF(COUNT(K12,W12,AI12,AU12)=0, "", ROUND(AVERAGE(K12,W12,AI12,AU12), 0)) | ... BK12: =IF(COUNT(O12,AA12,AM12,AY12)=0, "", ROUND(AVERAGE(O12,AA12,AM12,AY12), 0)) | BL12: =IF(COUNT(AZ12:BG12,BJ12:BK12)=0, "", ROUND(AVERAGE(AZ12:BG12,BJ12:BK12), 0))
A13: =IF('Class Info'!A13="","", 'Class Info'!A13) | B13: =IF('Class Info'!B13="","", 'Class Info'!B13) | C13: =IF('Class Info'!C13="","", 'Class Info'!C13) | AZ13: =IF(COUNT(D13,P13,AB13,AN13)=0, "", ROUND(AVERAGE(D13,P13,AB13,AN13), 0)) | BA13: =IF(COUNT(E13,Q13,AC13,AO13)=0, "", ROUND(AVERAGE(E13,Q13,AC13,AO13), 0)) | BB13: =IF(COUNT(F13,R13,AD13,AP13)=0, "", ROUND(AVERAGE(F13,R13,AD13,AP13), 0)) | BC13: =IF(COUNT(G13,S13,AE13,AQ13)=0, "", ROUND(AVERAGE(G13,S13,AE13,AQ13), 0)) | BD13: =IF(COUNT(H13,T13,AF13,AR13)=0, "", ROUND(AVERAGE(H13,T13,AF13,AR13), 0)) | BE13: =IF(COUNT(I13,U13,AG13,AS13)=0, "", ROUND(AVERAGE(I13,U13,AG13,AS13), 0)) | BF13: =IF(COUNT(J13,V13,AH13,AT13)=0, "", ROUND(AVERAGE(J13,V13,AH13,AT13), 0)) | BG13: =IF(COUNT(K13,W13,AI13,AU13)=0, "", ROUND(AVERAGE(K13,W13,AI13,AU13), 0)) | ... BK13: =IF(COUNT(O13,AA13,AM13,AY13)=0, "", ROUND(AVERAGE(O13,AA13,AM13,AY13), 0)) | BL13: =IF(COUNT(AZ13:BG13,BJ13:BK13)=0, "", ROUND(AVERAGE(AZ13:BG13,BJ13:BK13), 0))
A14: =IF('Class Info'!A14="","", 'Class Info'!A14) | B14: =IF('Class Info'!B14="","", 'Class Info'!B14) | C14: =IF('Class Info'!C14="","", 'Class Info'!C14) | AZ14: =IF(COUNT(D14,P14,AB14,AN14)=0, "", ROUND(AVERAGE(D14,P14,AB14,AN14), 0)) | BA14: =IF(COUNT(E14,Q14,AC14,AO14)=0, "", ROUND(AVERAGE(E14,Q14,AC14,AO14), 0)) | BB14: =IF(COUNT(F14,R14,AD14,AP14)=0, "", ROUND(AVERAGE(F14,R14,AD14,AP14), 0)) | BC14: =IF(COUNT(G14,S14,AE14,AQ14)=0, "", ROUND(AVERAGE(G14,S14,AE14,AQ14), 0)) | BD14: =IF(COUNT(H14,T14,AF14,AR14)=0, "", ROUND(AVERAGE(H14,T14,AF14,AR14), 0)) | BE14: =IF(COUNT(I14,U14,AG14,AS14)=0, "", ROUND(AVERAGE(I14,U14,AG14,AS14), 0)) | BF14: =IF(COUNT(J14,V14,AH14,AT14)=0, "", ROUND(AVERAGE(J14,V14,AH14,AT14), 0)) | BG14: =IF(COUNT(K14,W14,AI14,AU14)=0, "", ROUND(AVERAGE(K14,W14,AI14,AU14), 0)) | ... BK14: =IF(COUNT(O14,AA14,AM14,AY14)=0, "", ROUND(AVERAGE(O14,AA14,AM14,AY14), 0)) | BL14: =IF(COUNT(AZ14:BG14,BJ14:BK14)=0, "", ROUND(AVERAGE(AZ14:BG14,BJ14:BK14), 0))
... A22: =IF('Class Info'!A22="","", 'Class Info'!A22) | B22: =IF('Class Info'!B22="","", 'Class Info'!B22) | C22: =IF('Class Info'!C22="","", 'Class Info'!C22) | AZ22: =IF(COUNT(D22,P22,AB22,AN22)=0, "", ROUND(AVERAGE(D22,P22,AB22,AN22), 0)) | BA22: =IF(COUNT(E22,Q22,AC22,AO22)=0, "", ROUND(AVERAGE(E22,Q22,AC22,AO22), 0)) | BB22: =IF(COUNT(F22,R22,AD22,AP22)=0, "", ROUND(AVERAGE(F22,R22,AD22,AP22), 0)) | BC22: =IF(COUNT(G22,S22,AE22,AQ22)=0, "", ROUND(AVERAGE(G22,S22,AE22,AQ22), 0)) | BD22: =IF(COUNT(H22,T22,AF22,AR22)=0, "", ROUND(AVERAGE(H22,T22,AF22,AR22), 0)) | BE22: =IF(COUNT(I22,U22,AG22,AS22)=0, "", ROUND(AVERAGE(I22,U22,AG22,AS22), 0)) | BF22: =IF(COUNT(J22,V22,AH22,AT22)=0, "", ROUND(AVERAGE(J22,V22,AH22,AT22), 0)) | BG22: =IF(COUNT(K22,W22,AI22,AU22)=0, "", ROUND(AVERAGE(K22,W22,AI22,AU22), 0)) | ... BK22: =IF(COUNT(O22,AA22,AM22,AY22)=0, "", ROUND(AVERAGE(O22,AA22,AM22,AY22), 0)) | BL22: =IF(COUNT(AZ22:BG22,BJ22:BK22)=0, "", ROUND(AVERAGE(AZ22:BG22,BJ22:BK22), 0))
A23: =IF('Class Info'!A23="","", 'Class Info'!A23) | B23: =IF('Class Info'!B23="","", 'Class Info'!B23) | C23: =IF('Class Info'!C23="","", 'Class Info'!C23) | AZ23: =IF(COUNT(D23,P23,AB23,AN23)=0, "", ROUND(AVERAGE(D23,P23,AB23,AN23), 0)) | BA23: =IF(COUNT(E23,Q23,AC23,AO23)=0, "", ROUND(AVERAGE(E23,Q23,AC23,AO23), 0)) | BB23: =IF(COUNT(F23,R23,AD23,AP23)=0, "", ROUND(AVERAGE(F23,R23,AD23,AP23), 0)) | BC23: =IF(COUNT(G23,S23,AE23,AQ23)=0, "", ROUND(AVERAGE(G23,S23,AE23,AQ23), 0)) | BD23: =IF(COUNT(H23,T23,AF23,AR23)=0, "", ROUND(AVERAGE(H23,T23,AF23,AR23), 0)) | BE23: =IF(COUNT(I23,U23,AG23,AS23)=0, "", ROUND(AVERAGE(I23,U23,AG23,AS23), 0)) | BF23: =IF(COUNT(J23,V23,AH23,AT23)=0, "", ROUND(AVERAGE(J23,V23,AH23,AT23), 0)) | BG23: =IF(COUNT(K23,W23,AI23,AU23)=0, "", ROUND(AVERAGE(K23,W23,AI23,AU23), 0)) | ... BK23: =IF(COUNT(O23,AA23,AM23,AY23)=0, "", ROUND(AVERAGE(O23,AA23,AM23,AY23), 0))
A24: =IF('Class Info'!A24="","", 'Class Info'!A24) | B24: =IF('Class Info'!B24="","", 'Class Info'!B24) | C24: =IF('Class Info'!C24="","", 'Class Info'!C24) | AZ24: =IF(COUNT(D24,P24,AB24,AN24)=0, "", ROUND(AVERAGE(D24,P24,AB24,AN24), 0)) | BA24: =IF(COUNT(E24,Q24,AC24,AO24)=0, "", ROUND(AVERAGE(E24,Q24,AC24,AO24), 0)) | BB24: =IF(COUNT(F24,R24,AD24,AP24)=0, "", ROUND(AVERAGE(F24,R24,AD24,AP24), 0)) | BC24: =IF(COUNT(G24,S24,AE24,AQ24)=0, "", ROUND(AVERAGE(G24,S24,AE24,AQ24), 0)) | BD24: =IF(COUNT(H24,T24,AF24,AR24)=0, "", ROUND(AVERAGE(H24,T24,AF24,AR24), 0)) | BE24: =IF(COUNT(I24,U24,AG24,AS24)=0, "", ROUND(AVERAGE(I24,U24,AG24,AS24), 0)) | BF24: =IF(COUNT(J24,V24,AH24,AT24)=0, "", ROUND(AVERAGE(J24,V24,AH24,AT24), 0)) | BG24: =IF(COUNT(K24,W24,AI24,AU24)=0, "", ROUND(AVERAGE(K24,W24,AI24,AU24), 0)) | ... BK24: =IF(COUNT(O24,AA24,AM24,AY24)=0, "", ROUND(AVERAGE(O24,AA24,AM24,AY24), 0))
A25: =IF('Class Info'!A25="","", 'Class Info'!A25) | B25: =IF('Class Info'!B25="","", 'Class Info'!B25) | C25: =IF('Class Info'!C25="","", 'Class Info'!C25) | AZ25: =IF(COUNT(D25,P25,AB25,AN25)=0, "", ROUND(AVERAGE(D25,P25,AB25,AN25), 0)) | BA25: =IF(COUNT(E25,Q25,AC25,AO25)=0, "", ROUND(AVERAGE(E25,Q25,AC25,AO25), 0)) | BB25: =IF(COUNT(F25,R25,AD25,AP25)=0, "", ROUND(AVERAGE(F25,R25,AD25,AP25), 0)) | BC25: =IF(COUNT(G25,S25,AE25,AQ25)=0, "", ROUND(AVERAGE(G25,S25,AE25,AQ25), 0)) | BD25: =IF(COUNT(H25,T25,AF25,AR25)=0, "", ROUND(AVERAGE(H25,T25,AF25,AR25), 0)) | BE25: =IF(COUNT(I25,U25,AG25,AS25)=0, "", ROUND(AVERAGE(I25,U25,AG25,AS25), 0)) | BF25: =IF(COUNT(J25,V25,AH25,AT25)=0, "", ROUND(AVERAGE(J25,V25,AH25,AT25), 0)) | BG25: =IF(COUNT(K25,W25,AI25,AU25)=0, "", ROUND(AVERAGE(K25,W25,AI25,AU25), 0)) | ... BK25: =IF(COUNT(O25,AA25,AM25,AY25)=0, "", ROUND(AVERAGE(O25,AA25,AM25,AY25), 0))
A26: =IF('Class Info'!A26="","", 'Class Info'!A26) | B26: =IF('Class Info'!B26="","", 'Class Info'!B26) | C26: =IF('Class Info'!C26="","", 'Class Info'!C26) | AZ26: =IF(COUNT(D26,P26,AB26,AN26)=0, "", ROUND(AVERAGE(D26,P26,AB26,AN26), 0)) | BA26: =IF(COUNT(E26,Q26,AC26,AO26)=0, "", ROUND(AVERAGE(E26,Q26,AC26,AO26), 0)) | BB26: =IF(COUNT(F26,R26,AD26,AP26)=0, "", ROUND(AVERAGE(F26,R26,AD26,AP26), 0)) | BC26: =IF(COUNT(G26,S26,AE26,AQ26)=0, "", ROUND(AVERAGE(G26,S26,AE26,AQ26), 0)) | BD26: =IF(COUNT(H26,T26,AF26,AR26)=0, "", ROUND(AVERAGE(H26,T26,AF26,AR26), 0)) | BE26: =IF(COUNT(I26,U26,AG26,AS26)=0, "", ROUND(AVERAGE(I26,U26,AG26,AS26), 0)) | BF26: =IF(COUNT(J26,V26,AH26,AT26)=0, "", ROUND(AVERAGE(J26,V26,AH26,AT26), 0)) | BG26: =IF(COUNT(K26,W26,AI26,AU26)=0, "", ROUND(AVERAGE(K26,W26,AI26,AU26), 0)) | ... BK26: =IF(COUNT(O26,AA26,AM26,AY26)=0, "", ROUND(AVERAGE(O26,AA26,AM26,AY26), 0))
A27: =IF('Class Info'!A27="","", 'Class Info'!A27) | B27: =IF('Class Info'!B27="","", 'Class Info'!B27) | C27: =IF('Class Info'!C27="","", 'Class Info'!C27) | AZ27: =IF(COUNT(D27,P27,AB27,AN27)=0, "", ROUND(AVERAGE(D27,P27,AB27,AN27), 0)) | BA27: =IF(COUNT(E27,Q27,AC27,AO27)=0, "", ROUND(AVERAGE(E27,Q27,AC27,AO27), 0)) | BB27: =IF(COUNT(F27,R27,AD27,AP27)=0, "", ROUND(AVERAGE(F27,R27,AD27,AP27), 0)) | BC27: =IF(COUNT(G27,S27,AE27,AQ27)=0, "", ROUND(AVERAGE(G27,S27,AE27,AQ27), 0)) | BD27: =IF(COUNT(H27,T27,AF27,AR27)=0, "", ROUND(AVERAGE(H27,T27,AF27,AR27), 0)) | BE27: =IF(COUNT(I27,U27,AG27,AS27)=0, "", ROUND(AVERAGE(I27,U27,AG27,AS27), 0)) | BF27: =IF(COUNT(J27,V27,AH27,AT27)=0, "", ROUND(AVERAGE(J27,V27,AH27,AT27), 0)) | BG27: =IF(COUNT(K27,W27,AI27,AU27)=0, "", ROUND(AVERAGE(K27,W27,AI27,AU27), 0)) | ... BK27: =IF(COUNT(O27,AA27,AM27,AY27)=0, "", ROUND(AVERAGE(O27,AA27,AM27,AY27), 0))
A28: =IF('Class Info'!A28="","", 'Class Info'!A28) | B28: =IF('Class Info'!B28="","", 'Class Info'!B28) | C28: =IF('Class Info'!C28="","", 'Class Info'!C28) | AZ28: =IF(COUNT(D28,P28,AB28,AN28)=0, "", ROUND(AVERAGE(D28,P28,AB28,AN28), 0)) | BA28: =IF(COUNT(E28,Q28,AC28,AO28)=0, "", ROUND(AVERAGE(E28,Q28,AC28,AO28), 0)) | BB28: =IF(COUNT(F28,R28,AD28,AP28)=0, "", ROUND(AVERAGE(F28,R28,AD28,AP28), 0)) | BC28: =IF(COUNT(G28,S28,AE28,AQ28)=0, "", ROUND(AVERAGE(G28,S28,AE28,AQ28), 0)) | BD28: =IF(COUNT(H28,T28,AF28,AR28)=0, "", ROUND(AVERAGE(H28,T28,AF28,AR28), 0)) | BE28: =IF(COUNT(I28,U28,AG28,AS28)=0, "", ROUND(AVERAGE(I28,U28,AG28,AS28), 0)) | BF28: =IF(COUNT(J28,V28,AH28,AT28)=0, "", ROUND(AVERAGE(J28,V28,AH28,AT28), 0)) | BG28: =IF(COUNT(K28,W28,AI28,AU28)=0, "", ROUND(AVERAGE(K28,W28,AI28,AU28), 0)) | ... BK28: =IF(COUNT(O28,AA28,AM28,AY28)=0, "", ROUND(AVERAGE(O28,AA28,AM28,AY28), 0))
A29: =IF('Class Info'!A29="","", 'Class Info'!A29) | B29: =IF('Class Info'!B29="","", 'Class Info'!B29) | C29: =IF('Class Info'!C29="","", 'Class Info'!C29) | AZ29: =IF(COUNT(D29,P29,AB29,AN29)=0, "", ROUND(AVERAGE(D29,P29,AB29,AN29), 0)) | BA29: =IF(COUNT(E29,Q29,AC29,AO29)=0, "", ROUND(AVERAGE(E29,Q29,AC29,AO29), 0)) | BB29: =IF(COUNT(F29,R29,AD29,AP29)=0, "", ROUND(AVERAGE(F29,R29,AD29,AP29), 0)) | BC29: =IF(COUNT(G29,S29,AE29,AQ29)=0, "", ROUND(AVERAGE(G29,S29,AE29,AQ29), 0)) | BD29: =IF(COUNT(H29,T29,AF29,AR29)=0, "", ROUND(AVERAGE(H29,T29,AF29,AR29), 0)) | BE29: =IF(COUNT(I29,U29,AG29,AS29)=0, "", ROUND(AVERAGE(I29,U29,AG29,AS29), 0)) | BF29: =IF(COUNT(J29,V29,AH29,AT29)=0, "", ROUND(AVERAGE(J29,V29,AH29,AT29), 0)) | BG29: =IF(COUNT(K29,W29,AI29,AU29)=0, "", ROUND(AVERAGE(K29,W29,AI29,AU29), 0)) | ... BK29: =IF(COUNT(O29,AA29,AM29,AY29)=0, "", ROUND(AVERAGE(O29,AA29,AM29,AY29), 0))
A30: =IF('Class Info'!A30="","", 'Class Info'!A30) | B30: =IF('Class Info'!B30="","", 'Class Info'!B30) | C30: =IF('Class Info'!C30="","", 'Class Info'!C30) | AZ30: =IF(COUNT(D30,P30,AB30,AN30)=0, "", ROUND(AVERAGE(D30,P30,AB30,AN30), 0)) | BA30: =IF(COUNT(E30,Q30,AC30,AO30)=0, "", ROUND(AVERAGE(E30,Q30,AC30,AO30), 0)) | BB30: =IF(COUNT(F30,R30,AD30,AP30)=0, "", ROUND(AVERAGE(F30,R30,AD30,AP30), 0)) | BC30: =IF(COUNT(G30,S30,AE30,AQ30)=0, "", ROUND(AVERAGE(G30,S30,AE30,AQ30), 0)) | BD30: =IF(COUNT(H30,T30,AF30,AR30)=0, "", ROUND(AVERAGE(H30,T30,AF30,AR30), 0)) | BE30: =IF(COUNT(I30,U30,AG30,AS30)=0, "", ROUND(AVERAGE(I30,U30,AG30,AS30), 0)) | BF30: =IF(COUNT(J30,V30,AH30,AT30)=0, "", ROUND(AVERAGE(J30,V30,AH30,AT30), 0)) | BG30: =IF(COUNT(K30,W30,AI30,AU30)=0, "", ROUND(AVERAGE(K30,W30,AI30,AU30), 0)) | ... BK30: =IF(COUNT(O30,AA30,AM30,AY30)=0, "", ROUND(AVERAGE(O30,AA30,AM30,AY30), 0))
A31: =IF('Class Info'!A31="","", 'Class Info'!A31) | B31: =IF('Class Info'!B31="","", 'Class Info'!B31) | C31: =IF('Class Info'!C31="","", 'Class Info'!C31) | AZ31: =IF(COUNT(D31,P31,AB31,AN31)=0, "", ROUND(AVERAGE(D31,P31,AB31,AN31), 0)) | BA31: =IF(COUNT(E31,Q31,AC31,AO31)=0, "", ROUND(AVERAGE(E31,Q31,AC31,AO31), 0)) | BB31: =IF(COUNT(F31,R31,AD31,AP31)=0, "", ROUND(AVERAGE(F31,R31,AD31,AP31), 0)) | BC31: =IF(COUNT(G31,S31,AE31,AQ31)=0, "", ROUND(AVERAGE(G31,S31,AE31,AQ31), 0)) | BD31: =IF(COUNT(H31,T31,AF31,AR31)=0, "", ROUND(AVERAGE(H31,T31,AF31,AR31), 0)) | BE31: =IF(COUNT(I31,U31,AG31,AS31)=0, "", ROUND(AVERAGE(I31,U31,AG31,AS31), 0)) | BF31: =IF(COUNT(J31,V31,AH31,AT31)=0, "", ROUND(AVERAGE(J31,V31,AH31,AT31), 0)) | BG31: =IF(COUNT(K31,W31,AI31,AU31)=0, "", ROUND(AVERAGE(K31,W31,AI31,AU31), 0)) | ... BK31: =IF(COUNT(O31,AA31,AM31,AY31)=0, "", ROUND(AVERAGE(O31,AA31,AM31,AY31), 0))
A32: =IF('Class Info'!A32="","", 'Class Info'!A32) | B32: =IF('Class Info'!B32="","", 'Class Info'!B32) | C32: =IF('Class Info'!C32="","", 'Class Info'!C32) | AZ32: =IF(COUNT(D32,P32,AB32,AN32)=0, "", ROUND(AVERAGE(D32,P32,AB32,AN32), 0)) | BA32: =IF(COUNT(E32,Q32,AC32,AO32)=0, "", ROUND(AVERAGE(E32,Q32,AC32,AO32), 0)) | BB32: =IF(COUNT(F32,R32,AD32,AP32)=0, "", ROUND(AVERAGE(F32,R32,AD32,AP32), 0)) | BC32: =IF(COUNT(G32,S32,AE32,AQ32)=0, "", ROUND(AVERAGE(G32,S32,AE32,AQ32), 0)) | BD32: =IF(COUNT(H32,T32,AF32,AR32)=0, "", ROUND(AVERAGE(H32,T32,AF32,AR32), 0)) | BE32: =IF(COUNT(I32,U32,AG32,AS32)=0, "", ROUND(AVERAGE(I32,U32,AG32,AS32), 0)) | BF32: =IF(COUNT(J32,V32,AH32,AT32)=0, "", ROUND(AVERAGE(J32,V32,AH32,AT32), 0)) | BG32: =IF(COUNT(K32,W32,AI32,AU32)=0, "", ROUND(AVERAGE(K32,W32,AI32,AU32), 0)) | ... BK32: =IF(COUNT(O32,AA32,AM32,AY32)=0, "", ROUND(AVERAGE(O32,AA32,AM32,AY32), 0))
A33: =IF('Class Info'!A33="","", 'Class Info'!A33) | B33: =IF('Class Info'!B33="","", 'Class Info'!B33) | C33: =IF('Class Info'!C33="","", 'Class Info'!C33) | AZ33: =IF(COUNT(D33,P33,AB33,AN33)=0, "", ROUND(AVERAGE(D33,P33,AB33,AN33), 0)) | BA33: =IF(COUNT(E33,Q33,AC33,AO33)=0, "", ROUND(AVERAGE(E33,Q33,AC33,AO33), 0)) | BB33: =IF(COUNT(F33,R33,AD33,AP33)=0, "", ROUND(AVERAGE(F33,R33,AD33,AP33), 0)) | BC33: =IF(COUNT(G33,S33,AE33,AQ33)=0, "", ROUND(AVERAGE(G33,S33,AE33,AQ33), 0)) | BD33: =IF(COUNT(H33,T33,AF33,AR33)=0, "", ROUND(AVERAGE(H33,T33,AF33,AR33), 0)) | BE33: =IF(COUNT(I33,U33,AG33,AS33)=0, "", ROUND(AVERAGE(I33,U33,AG33,AS33), 0)) | BF33: =IF(COUNT(J33,V33,AH33,AT33)=0, "", ROUND(AVERAGE(J33,V33,AH33,AT33), 0)) | BG33: =IF(COUNT(K33,W33,AI33,AU33)=0, "", ROUND(AVERAGE(K33,W33,AI33,AU33), 0)) | ... BK33: =IF(COUNT(O33,AA33,AM33,AY33)=0, "", ROUND(AVERAGE(O33,AA33,AM33,AY33), 0))
A34: =IF('Class Info'!A34="","", 'Class Info'!A34) | B34: =IF('Class Info'!B34="","", 'Class Info'!B34) | C34: =IF('Class Info'!C34="","", 'Class Info'!C34) | AZ34: =IF(COUNT(D34,P34,AB34,AN34)=0, "", ROUND(AVERAGE(D34,P34,AB34,AN34), 0)) | BA34: =IF(COUNT(E34,Q34,AC34,AO34)=0, "", ROUND(AVERAGE(E34,Q34,AC34,AO34), 0)) | BB34: =IF(COUNT(F34,R34,AD34,AP34)=0, "", ROUND(AVERAGE(F34,R34,AD34,AP34), 0)) | BC34: =IF(COUNT(G34,S34,AE34,AQ34)=0, "", ROUND(AVERAGE(G34,S34,AE34,AQ34), 0)) | BD34: =IF(COUNT(H34,T34,AF34,AR34)=0, "", ROUND(AVERAGE(H34,T34,AF34,AR34), 0)) | BE34: =IF(COUNT(I34,U34,AG34,AS34)=0, "", ROUND(AVERAGE(I34,U34,AG34,AS34), 0)) | BF34: =IF(COUNT(J34,V34,AH34,AT34)=0, "", ROUND(AVERAGE(J34,V34,AH34,AT34), 0)) | BG34: =IF(COUNT(K34,W34,AI34,AU34)=0, "", ROUND(AVERAGE(K34,W34,AI34,AU34), 0)) | ... BK34: =IF(COUNT(O34,AA34,AM34,AY34)=0, "", ROUND(AVERAGE(O34,AA34,AM34,AY34), 0))
... A51: =IF('Class Info'!A51="","", 'Class Info'!A51) | B51: =IF('Class Info'!B51="","", 'Class Info'!B51) | C51: =IF('Class Info'!C51="","", 'Class Info'!C51) | AZ51: =IF(COUNT(D51,P51,AB51,AN51)=0, "", ROUND(AVERAGE(D51,P51,AB51,AN51), 0)) | BA51: =IF(COUNT(E51,Q51,AC51,AO51)=0, "", ROUND(AVERAGE(E51,Q51,AC51,AO51), 0)) | BB51: =IF(COUNT(F51,R51,AD51,AP51)=0, "", ROUND(AVERAGE(F51,R51,AD51,AP51), 0)) | BC51: =IF(COUNT(G51,S51,AE51,AQ51)=0, "", ROUND(AVERAGE(G51,S51,AE51,AQ51), 0)) | BD51: =IF(COUNT(H51,T51,AF51,AR51)=0, "", ROUND(AVERAGE(H51,T51,AF51,AR51), 0)) | BE51: =IF(COUNT(I51,U51,AG51,AS51)=0, "", ROUND(AVERAGE(I51,U51,AG51,AS51), 0)) | BF51: =IF(COUNT(J51,V51,AH51,AT51)=0, "", ROUND(AVERAGE(J51,V51,AH51,AT51), 0)) | BG51: =IF(COUNT(K51,W51,AI51,AU51)=0, "", ROUND(AVERAGE(K51,W51,AI51,AU51), 0)) | ... BK51: =IF(COUNT(O51,AA51,AM51,AY51)=0, "", ROUND(AVERAGE(O51,AA51,AM51,AY51), 0))
A52: =IF('Class Info'!A52="","", 'Class Info'!A52) | B52: =IF('Class Info'!B52="","", 'Class Info'!B52) | C52: =IF('Class Info'!C52="","", 'Class Info'!C52)
A53: =IF('Class Info'!A53="","", 'Class Info'!A53) | B53: =IF('Class Info'!B53="","", 'Class Info'!B53) | C53: =IF('Class Info'!C53="","", 'Class Info'!C53)
A54: =IF('Class Info'!A54="","", 'Class Info'!A54) | B54: =IF('Class Info'!B54="","", 'Class Info'!B54) | C54: =IF('Class Info'!C54="","", 'Class Info'!C54)
A55: =IF('Class Info'!A55="","", 'Class Info'!A55) | B55: =IF('Class Info'!B55="","", 'Class Info'!B55) | C55: =IF('Class Info'!C55="","", 'Class Info'!C55)
A56: =IF('Class Info'!A56="","", 'Class Info'!A56) | B56: =IF('Class Info'!B56="","", 'Class Info'!B56) | C56: =IF('Class Info'!C56="","", 'Class Info'!C56)
A57: =IF('Class Info'!A57="","", 'Class Info'!A57) | B57: =IF('Class Info'!B57="","", 'Class Info'!B57) | C57: =IF('Class Info'!C57="","", 'Class Info'!C57)
A58: =IF('Class Info'!A58="","", 'Class Info'!A58) | B58: =IF('Class Info'!B58="","", 'Class Info'!B58) | C58: =IF('Class Info'!C58="","", 'Class Info'!C58)
A59: =IF('Class Info'!A59="","", 'Class Info'!A59) | B59: =IF('Class Info'!B59="","", 'Class Info'!B59) | C59: =IF('Class Info'!C59="","", 'Class Info'!C59)
A60: =IF('Class Info'!A60="","", 'Class Info'!A60) | B60: =IF('Class Info'!B60="","", 'Class Info'!B60) | C60: =IF('Class Info'!C60="","", 'Class Info'!C60)
A61: =IF('Class Info'!A61="","", 'Class Info'!A61) | B61: =IF('Class Info'!B61="","", 'Class Info'!B61) | C61: =IF('Class Info'!C61="","", 'Class Info'!C61)
A62: =IF('Class Info'!A62="","", 'Class Info'!A62) | B62: =IF('Class Info'!B62="","", 'Class Info'!B62) | C62: =IF('Class Info'!C62="","", 'Class Info'!C62)
A63: =IF('Class Info'!A63="","", 'Class Info'!A63) | B63: =IF('Class Info'!B63="","", 'Class Info'!B63) | C63: =IF('Class Info'!C63="","", 'Class Info'!C63)
...

Sheet Export
A1: # Read Only
A2: learner.lrn | B2: learner.last_name | C2: learner.first_name | D2: learner.middle_name | E2: learner.extn | F2: learner.birthdate | G2: learner.sex | H2: credential_presented_for_grade_1 | I2: enrollment.name_of_school | J2: enrollment.school_address | K2: enrollment.pept.rating | L2: enrollment.pept.date_of_examination | M2: enrollment.pept.name_of_testing_center | N2: enrollment.others | O2: enrollment.remark | P2: record_4.quarterly.filipino.quarter_1 | Q2: record_4.quarterly.filipino.quarter_2 | R2: record_4.quarterly.filipino.quarter_3 | S2: record_4.quarterly.filipino.quarter_4 | T2: record_4.quarterly.english.quarter_1 | U2: record_4.quarterly.english.quarter_2 | V2: record_4.quarterly.english.quarter_3 | W2: record_4.quarterly.english.quarter_4 | X2: record_4.quarterly.mathematics.quarter_1 | Y2: record_4.quarterly.mathematics.quarter_2 | Z2: record_4.quarterly.mathematics.quarter_3 | AA2: record_4.quarterly.mathematics.quarter_4 | AB2: record_4.quarterly.science.quarter_1 | AC2: record_4.quarterly.science.quarter_2 | AD2: record_4.quarterly.science.quarter_3 | AE2: record_4.quarterly.science.quarter_4 | AF2: record_4.quarterly.gmrc.quarter_1 | AG2: record_4.quarterly.gmrc.quarter_2 | AH2: record_4.quarterly.gmrc.quarter_3 | AI2: record_4.quarterly.gmrc.quarter_4 | AJ2: record_4.quarterly.araling_panlipunan.quarter_1 | AK2: record_4.quarterly.araling_panlipunan.quarter_2 | AL2: record_4.quarterly.araling_panlipunan.quarter_3 | AM2: record_4.quarterly.araling_panlipunan.quarter_4 | AN2: record_4.quarterly.epp.quarter_1 | AO2: record_4.quarterly.epp.quarter_2 | AP2: record_4.quarterly.epp.quarter_3 | AQ2: record_4.quarterly.epp.quarter_4 | AR2: record_4.quarterly.mapeh.quarter_1 | AS2: record_4.quarterly.mapeh.quarter_2 | AT2: record_4.quarterly.mapeh.quarter_3 | AU2: record_4.quarterly.mapeh.quarter_4 | AV2: record_4.quarterly.music_and_arts.quarter_1 | AW2: record_4.quarterly.music_and_arts.quarter_2 | AX2: record_4.quarterly.music_and_arts.quarter_3 | AY2: record_4.quarterly.music_and_arts.quarter_4 | AZ2: record_4.quarterly.physical_education_and_health.quarter_1 | BA2: record_4.quarterly.physical_education_and_health.quarter_2 | BB2: record_4.quarterly.physical_education_and_health.quarter_3 | BC2: record_4.quarterly.physical_education_and_health.quarter_4 | BD2: record_4.quarterly.arabic_language.quarter_1 | BE2: record_4.quarterly.arabic_language.quarter_2 | BF2: record_4.quarterly.arabic_language.quarter_3 | BG2: record_4.quarterly.arabic_language.quarter_4 | BH2: record_4.quarterly.islamic_values_education.quarter_1 | BI2: record_4.quarterly.islamic_values_education.quarter_2 | BJ2: record_4.quarterly.islamic_values_education.quarter_3 | BK2: record_4.quarterly.islamic_values_education.quarter_4 | BL2: record_4.final_rating.filipino | BM2: record_4.final_rating.english | BN2: record_4.final_rating.mathematics | BO2: record_4.final_rating.science | BP2: record_4.final_rating.gmrc | BQ2: record_4.final_rating.araling_panlipunan | BR2: record_4.final_rating.epp | BS2: record_4.final_rating.mapeh | BT2: record_4.final_rating.arabic_language | BU2: record_4.final_rating.islamic_values_education | BV2: record_4.general_average
A3: =IF('Class Info'!A3="","", 'Class Info'!A3) | B3: =IF('Class Info'!B3="","", 'Class Info'!B3) | C3: =IF('Class Info'!C3="","", 'Class Info'!C3) | D3: =IF('Class Info'!D3="","", 'Class Info'!D3) | E3: =IF('Class Info'!E3="","", 'Class Info'!E3) | F3: =IF('Class Info'!F3="","", 'Class Info'!F3) | G3: =IF('Class Info'!G3="","", 'Class Info'!G3) | H3: =IF('Class Info'!H3="","", 'Class Info'!H3) | ... O3: =IF('Class Info'!O3="","", 'Class Info'!O3) | P3: =IF(Grades!D3="","", Grades!D3) | Q3: =IF(Grades!P3="","", Grades!P3) | R3: =IF(Grades!AB3="","", Grades!AB3) | S3: =IF(Grades!AN3="","", Grades!AN3) | T3: =IF(Grades!E3="","", Grades!E3) | U3: =IF(Grades!Q3="","", Grades!Q3) | V3: =IF(Grades!AC3="","", Grades!AC3) | W3: =IF(Grades!AO3="","", Grades!AO3) | X3: =IF(Grades!F3="","", Grades!F3) | Y3: =IF(Grades!R3="","", Grades!R3) | Z3: =IF(Grades!AD3="","", Grades!AD3) | AA3: =IF(Grades!AP3="","", Grades!AP3) | AB3: =IF(Grades!G3="","", Grades!G3) | AC3: =IF(Grades!S3="","", Grades!S3) | AD3: =IF(Grades!AE3="","", Grades!AE3) | AE3: =IF(Grades!AQ3="","", Grades!AQ3) | AF3: =IF(Grades!H3="","", Grades!H3) | AG3: =IF(Grades!T3="","", Grades!T3) | AH3: =IF(Grades!AF3="","", Grades!AF3) | AI3: =IF(Grades!AR3="","", Grades!AR3) | AJ3: =IF(Grades!I3="","", Grades!I3) | AK3: =IF(Grades!U3="","", Grades!U3) | AL3: =IF(Grades!AG3="","", Grades!AG3) | AM3: =IF(Grades!AS3="","", Grades!AS3) | AN3: =IF(Grades!J3="","", Grades!J3) | AO3: =IF(Grades!V3="","", Grades!V3) | AP3: =IF(Grades!AH3="","", Grades!AH3) | AQ3: =IF(Grades!AT3="","", Grades!AT3) | AR3: =IF(Grades!K3="","", Grades!K3) | AS3: =IF(Grades!W3="","", Grades!W3) | AT3: =IF(Grades!AI3="","", Grades!AI3) | AU3: =IF(Grades!AU3="","", Grades!AU3) | AV3: =IF(Grades!L3="","", Grades!L3) | AW3: =IF(Grades!X3="","", Grades!X3) | AX3: =IF(Grades!AJ3="","", Grades!AJ3) | AY3: =IF(Grades!AV3="","", Grades!AV3) | AZ3: =IF(Grades!M3="","", Grades!M3) | BA3: =IF(Grades!Y3="","", Grades!Y3) | BB3: =IF(Grades!AK3="","", Grades!AK3) | BC3: =IF(Grades!AW3="","", Grades!AW3) | BD3: =IF(Grades!N3="","", Grades!N3) | BE3: =IF(Grades!Z3="","", Grades!Z3) | BF3: =IF(Grades!AL3="","", Grades!AL3) | BG3: =IF(Grades!AX3="","", Grades!AX3) | BH3: =IF(Grades!O3="","", Grades!O3) | BI3: =IF(Grades!AA3="","", Grades!AA3) | BJ3: =IF(Grades!AM3="","", Grades!AM3) | BK3: =IF(Grades!AY3="","", Grades!AY3) | BL3: =IF(Grades!AZ3="","", Grades!AZ3) | BM3: =IF(Grades!BA3="","", Grades!BA3) | BN3: =IF(Grades!BB3="","", Grades!BB3) | BO3: =IF(Grades!BC3="","", Grades!BC3) | BP3: =IF(Grades!BD3="","", Grades!BD3) | BQ3: =IF(Grades!BE3="","", Grades!BE3) | BR3: =IF(Grades!BF3="","", Grades!BF3) | BS3: =IF(Grades!BG3="","", Grades!BG3) | BT3: =IF(Grades!BJ3="","", Grades!BJ3) | BU3: =IF(Grades!BK3="","", Grades!BK3) | BV3: =IF(Grades!BL3="","", Grades!BL3)
A4: =IF('Class Info'!A4="","", 'Class Info'!A4) | B4: =IF('Class Info'!B4="","", 'Class Info'!B4) | C4: =IF('Class Info'!C4="","", 'Class Info'!C4) | D4: =IF('Class Info'!D4="","", 'Class Info'!D4) | E4: =IF('Class Info'!E4="","", 'Class Info'!E4) | F4: =IF('Class Info'!F4="","", 'Class Info'!F4) | G4: =IF('Class Info'!G4="","", 'Class Info'!G4) | H4: =IF('Class Info'!H4="","", 'Class Info'!H4) | ... O4: =IF('Class Info'!O4="","", 'Class Info'!O4) | P4: =IF(Grades!D4="","", Grades!D4) | Q4: =IF(Grades!P4="","", Grades!P4) | R4: =IF(Grades!AB4="","", Grades!AB4) | S4: =IF(Grades!AN4="","", Grades!AN4) | T4: =IF(Grades!E4="","", Grades!E4) | U4: =IF(Grades!Q4="","", Grades!Q4) | V4: =IF(Grades!AC4="","", Grades!AC4) | W4: =IF(Grades!AO4="","", Grades!AO4) | X4: =IF(Grades!F4="","", Grades!F4) | Y4: =IF(Grades!R4="","", Grades!R4) | Z4: =IF(Grades!AD4="","", Grades!AD4) | AA4: =IF(Grades!AP4="","", Grades!AP4) | AB4: =IF(Grades!G4="","", Grades!G4) | AC4: =IF(Grades!S4="","", Grades!S4) | AD4: =IF(Grades!AE4="","", Grades!AE4) | AE4: =IF(Grades!AQ4="","", Grades!AQ4) | AF4: =IF(Grades!H4="","", Grades!H4) | AG4: =IF(Grades!T4="","", Grades!T4) | AH4: =IF(Grades!AF4="","", Grades!AF4) | AI4: =IF(Grades!AR4="","", Grades!AR4) | AJ4: =IF(Grades!I4="","", Grades!I4) | AK4: =IF(Grades!U4="","", Grades!U4) | AL4: =IF(Grades!AG4="","", Grades!AG4) | AM4: =IF(Grades!AS4="","", Grades!AS4) | AN4: =IF(Grades!J4="","", Grades!J4) | AO4: =IF(Grades!V4="","", Grades!V4) | AP4: =IF(Grades!AH4="","", Grades!AH4) | AQ4: =IF(Grades!AT4="","", Grades!AT4) | AR4: =IF(Grades!K4="","", Grades!K4) | AS4: =IF(Grades!W4="","", Grades!W4) | AT4: =IF(Grades!AI4="","", Grades!AI4) | AU4: =IF(Grades!AU4="","", Grades!AU4) | AV4: =IF(Grades!L4="","", Grades!L4) | AW4: =IF(Grades!X4="","", Grades!X4) | AX4: =IF(Grades!AJ4="","", Grades!AJ4) | AY4: =IF(Grades!AV4="","", Grades!AV4) | AZ4: =IF(Grades!M4="","", Grades!M4) | BA4: =IF(Grades!Y4="","", Grades!Y4) | BB4: =IF(Grades!AK4="","", Grades!AK4) | BC4: =IF(Grades!AW4="","", Grades!AW4) | BD4: =IF(Grades!N4="","", Grades!N4) | BE4: =IF(Grades!Z4="","", Grades!Z4) | BF4: =IF(Grades!AL4="","", Grades!AL4) | BG4: =IF(Grades!AX4="","", Grades!AX4) | BH4: =IF(Grades!O4="","", Grades!O4) | BI4: =IF(Grades!AA4="","", Grades!AA4) | BJ4: =IF(Grades!AM4="","", Grades!AM4) | BK4: =IF(Grades!AY4="","", Grades!AY4) | BL4: =IF(Grades!AZ4="","", Grades!AZ4) | BM4: =IF(Grades!BA4="","", Grades!BA4) | BN4: =IF(Grades!BB4="","", Grades!BB4) | BO4: =IF(Grades!BC4="","", Grades!BC4) | BP4: =IF(Grades!BD4="","", Grades!BD4) | BQ4: =IF(Grades!BE4="","", Grades!BE4) | BR4: =IF(Grades!BF4="","", Grades!BF4) | BS4: =IF(Grades!BG4="","", Grades!BG4) | BT4: =IF(Grades!BJ4="","", Grades!BJ4) | BU4: =IF(Grades!BK4="","", Grades!BK4) | BV4: =IF(Grades!BL4="","", Grades!BL4)
A5: =IF('Class Info'!A5="","", 'Class Info'!A5) | B5: =IF('Class Info'!B5="","", 'Class Info'!B5) | C5: =IF('Class Info'!C5="","", 'Class Info'!C5) | D5: =IF('Class Info'!D5="","", 'Class Info'!D5) | E5: =IF('Class Info'!E5="","", 'Class Info'!E5) | F5: =IF('Class Info'!F5="","", 'Class Info'!F5) | G5: =IF('Class Info'!G5="","", 'Class Info'!G5) | H5: =IF('Class Info'!H5="","", 'Class Info'!H5) | ... O5: =IF('Class Info'!O5="","", 'Class Info'!O5) | P5: =IF(Grades!D5="","", Grades!D5) | Q5: =IF(Grades!P5="","", Grades!P5) | R5: =IF(Grades!AB5="","", Grades!AB5) | S5: =IF(Grades!AN5="","", Grades!AN5) | T5: =IF(Grades!E5="","", Grades!E5) | U5: =IF(Grades!Q5="","", Grades!Q5) | V5: =IF(Grades!AC5="","", Grades!AC5) | W5: =IF(Grades!AO5="","", Grades!AO5) | X5: =IF(Grades!F5="","", Grades!F5) | Y5: =IF(Grades!R5="","", Grades!R5) | Z5: =IF(Grades!AD5="","", Grades!AD5) | AA5: =IF(Grades!AP5="","", Grades!AP5) | AB5: =IF(Grades!G5="","", Grades!G5) | AC5: =IF(Grades!S5="","", Grades!S5) | AD5: =IF(Grades!AE5="","", Grades!AE5) | AE5: =IF(Grades!AQ5="","", Grades!AQ5) | AF5: =IF(Grades!H5="","", Grades!H5) | AG5: =IF(Grades!T5="","", Grades!T5) | AH5: =IF(Grades!AF5="","", Grades!AF5) | AI5: =IF(Grades!AR5="","", Grades!AR5) | AJ5: =IF(Grades!I5="","", Grades!I5) | AK5: =IF(Grades!U5="","", Grades!U5) | AL5: =IF(Grades!AG5="","", Grades!AG5) | AM5: =IF(Grades!AS5="","", Grades!AS5) | AN5: =IF(Grades!J5="","", Grades!J5) | AO5: =IF(Grades!V5="","", Grades!V5) | AP5: =IF(Grades!AH5="","", Grades!AH5) | AQ5: =IF(Grades!AT5="","", Grades!AT5) | AR5: =IF(Grades!K5="","", Grades!K5) | AS5: =IF(Grades!W5="","", Grades!W5) | AT5: =IF(Grades!AI5="","", Grades!AI5) | AU5: =IF(Grades!AU5="","", Grades!AU5) | AV5: =IF(Grades!L5="","", Grades!L5) | AW5: =IF(Grades!X5="","", Grades!X5) | AX5: =IF(Grades!AJ5="","", Grades!AJ5) | AY5: =IF(Grades!AV5="","", Grades!AV5) | AZ5: =IF(Grades!M5="","", Grades!M5) | BA5: =IF(Grades!Y5="","", Grades!Y5) | BB5: =IF(Grades!AK5="","", Grades!AK5) | BC5: =IF(Grades!AW5="","", Grades!AW5) | BD5: =IF(Grades!N5="","", Grades!N5) | BE5: =IF(Grades!Z5="","", Grades!Z5) | BF5: =IF(Grades!AL5="","", Grades!AL5) | BG5: =IF(Grades!AX5="","", Grades!AX5) | BH5: =IF(Grades!O5="","", Grades!O5) | BI5: =IF(Grades!AA5="","", Grades!AA5) | BJ5: =IF(Grades!AM5="","", Grades!AM5) | BK5: =IF(Grades!AY5="","", Grades!AY5) | BL5: =IF(Grades!AZ5="","", Grades!AZ5) | BM5: =IF(Grades!BA5="","", Grades!BA5) | BN5: =IF(Grades!BB5="","", Grades!BB5) | BO5: =IF(Grades!BC5="","", Grades!BC5) | BP5: =IF(Grades!BD5="","", Grades!BD5) | BQ5: =IF(Grades!BE5="","", Grades!BE5) | BR5: =IF(Grades!BF5="","", Grades!BF5) | BS5: =IF(Grades!BG5="","", Grades!BG5) | BT5: =IF(Grades!BJ5="","", Grades!BJ5) | BU5: =IF(Grades!BK5="","", Grades!BK5) | BV5: =IF(Grades!BL5="","", Grades!BL5)
A6: =IF('Class Info'!A6="","", 'Class Info'!A6) | B6: =IF('Class Info'!B6="","", 'Class Info'!B6) | C6: =IF('Class Info'!C6="","", 'Class Info'!C6) | D6: =IF('Class Info'!D6="","", 'Class Info'!D6) | E6: =IF('Class Info'!E6="","", 'Class Info'!E6) | F6: =IF('Class Info'!F6="","", 'Class Info'!F6) | G6: =IF('Class Info'!G6="","", 'Class Info'!G6) | H6: =IF('Class Info'!H6="","", 'Class Info'!H6) | ... O6: =IF('Class Info'!O6="","", 'Class Info'!O6) | P6: =IF(Grades!D6="","", Grades!D6) | Q6: =IF(Grades!P6="","", Grades!P6) | R6: =IF(Grades!AB6="","", Grades!AB6) | S6: =IF(Grades!AN6="","", Grades!AN6) | T6: =IF(Grades!E6="","", Grades!E6) | U6: =IF(Grades!Q6="","", Grades!Q6) | V6: =IF(Grades!AC6="","", Grades!AC6) | W6: =IF(Grades!AO6="","", Grades!AO6) | X6: =IF(Grades!F6="","", Grades!F6) | Y6: =IF(Grades!R6="","", Grades!R6) | Z6: =IF(Grades!AD6="","", Grades!AD6) | AA6: =IF(Grades!AP6="","", Grades!AP6) | AB6: =IF(Grades!G6="","", Grades!G6) | AC6: =IF(Grades!S6="","", Grades!S6) | AD6: =IF(Grades!AE6="","", Grades!AE6) | AE6: =IF(Grades!AQ6="","", Grades!AQ6) | AF6: =IF(Grades!H6="","", Grades!H6) | AG6: =IF(Grades!T6="","", Grades!T6) | AH6: =IF(Grades!AF6="","", Grades!AF6) | AI6: =IF(Grades!AR6="","", Grades!AR6) | AJ6: =IF(Grades!I6="","", Grades!I6) | AK6: =IF(Grades!U6="","", Grades!U6) | AL6: =IF(Grades!AG6="","", Grades!AG6) | AM6: =IF(Grades!AS6="","", Grades!AS6) | AN6: =IF(Grades!J6="","", Grades!J6) | AO6: =IF(Grades!V6="","", Grades!V6) | AP6: =IF(Grades!AH6="","", Grades!AH6) | AQ6: =IF(Grades!AT6="","", Grades!AT6) | AR6: =IF(Grades!K6="","", Grades!K6) | AS6: =IF(Grades!W6="","", Grades!W6) | AT6: =IF(Grades!AI6="","", Grades!AI6) | AU6: =IF(Grades!AU6="","", Grades!AU6) | AV6: =IF(Grades!L6="","", Grades!L6) | AW6: =IF(Grades!X6="","", Grades!X6) | AX6: =IF(Grades!AJ6="","", Grades!AJ6) | AY6: =IF(Grades!AV6="","", Grades!AV6) | AZ6: =IF(Grades!M6="","", Grades!M6) | BA6: =IF(Grades!Y6="","", Grades!Y6) | BB6: =IF(Grades!AK6="","", Grades!AK6) | BC6: =IF(Grades!AW6="","", Grades!AW6) | BD6: =IF(Grades!N6="","", Grades!N6) | BE6: =IF(Grades!Z6="","", Grades!Z6) | BF6: =IF(Grades!AL6="","", Grades!AL6) | BG6: =IF(Grades!AX6="","", Grades!AX6) | BH6: =IF(Grades!O6="","", Grades!O6) | BI6: =IF(Grades!AA6="","", Grades!AA6) | BJ6: =IF(Grades!AM6="","", Grades!AM6) | BK6: =IF(Grades!AY6="","", Grades!AY6) | BL6: =IF(Grades!AZ6="","", Grades!AZ6) | BM6: =IF(Grades!BA6="","", Grades!BA6) | BN6: =IF(Grades!BB6="","", Grades!BB6) | BO6: =IF(Grades!BC6="","", Grades!BC6) | BP6: =IF(Grades!BD6="","", Grades!BD6) | BQ6: =IF(Grades!BE6="","", Grades!BE6) | BR6: =IF(Grades!BF6="","", Grades!BF6) | BS6: =IF(Grades!BG6="","", Grades!BG6) | BT6: =IF(Grades!BJ6="","", Grades!BJ6) | BU6: =IF(Grades!BK6="","", Grades!BK6) | BV6: =IF(Grades!BL6="","", Grades!BL6)
A7: =IF('Class Info'!A7="","", 'Class Info'!A7) | B7: =IF('Class Info'!B7="","", 'Class Info'!B7) | C7: =IF('Class Info'!C7="","", 'Class Info'!C7) | D7: =IF('Class Info'!D7="","", 'Class Info'!D7) | E7: =IF('Class Info'!E7="","", 'Class Info'!E7) | F7: =IF('Class Info'!F7="","", 'Class Info'!F7) | G7: =IF('Class Info'!G7="","", 'Class Info'!G7) | H7: =IF('Class Info'!H7="","", 'Class Info'!H7) | ... O7: =IF('Class Info'!O7="","", 'Class Info'!O7) | P7: =IF(Grades!D7="","", Grades!D7) | Q7: =IF(Grades!P7="","", Grades!P7) | R7: =IF(Grades!AB7="","", Grades!AB7) | S7: =IF(Grades!AN7="","", Grades!AN7) | T7: =IF(Grades!E7="","", Grades!E7) | U7: =IF(Grades!Q7="","", Grades!Q7) | V7: =IF(Grades!AC7="","", Grades!AC7) | W7: =IF(Grades!AO7="","", Grades!AO7) | X7: =IF(Grades!F7="","", Grades!F7) | Y7: =IF(Grades!R7="","", Grades!R7) | Z7: =IF(Grades!AD7="","", Grades!AD7) | AA7: =IF(Grades!AP7="","", Grades!AP7) | AB7: =IF(Grades!G7="","", Grades!G7) | AC7: =IF(Grades!S7="","", Grades!S7) | AD7: =IF(Grades!AE7="","", Grades!AE7) | AE7: =IF(Grades!AQ7="","", Grades!AQ7) | AF7: =IF(Grades!H7="","", Grades!H7) | AG7: =IF(Grades!T7="","", Grades!T7) | AH7: =IF(Grades!AF7="","", Grades!AF7) | AI7: =IF(Grades!AR7="","", Grades!AR7) | AJ7: =IF(Grades!I7="","", Grades!I7) | AK7: =IF(Grades!U7="","", Grades!U7) | AL7: =IF(Grades!AG7="","", Grades!AG7) | AM7: =IF(Grades!AS7="","", Grades!AS7) | AN7: =IF(Grades!J7="","", Grades!J7) | AO7: =IF(Grades!V7="","", Grades!V7) | AP7: =IF(Grades!AH7="","", Grades!AH7) | AQ7: =IF(Grades!AT7="","", Grades!AT7) | AR7: =IF(Grades!K7="","", Grades!K7) | AS7: =IF(Grades!W7="","", Grades!W7) | AT7: =IF(Grades!AI7="","", Grades!AI7) | AU7: =IF(Grades!AU7="","", Grades!AU7) | AV7: =IF(Grades!L7="","", Grades!L7) | AW7: =IF(Grades!X7="","", Grades!X7) | AX7: =IF(Grades!AJ7="","", Grades!AJ7) | AY7: =IF(Grades!AV7="","", Grades!AV7) | AZ7: =IF(Grades!M7="","", Grades!M7) | BA7: =IF(Grades!Y7="","", Grades!Y7) | BB7: =IF(Grades!AK7="","", Grades!AK7) | BC7: =IF(Grades!AW7="","", Grades!AW7) | BD7: =IF(Grades!N7="","", Grades!N7) | BE7: =IF(Grades!Z7="","", Grades!Z7) | BF7: =IF(Grades!AL7="","", Grades!AL7) | BG7: =IF(Grades!AX7="","", Grades!AX7) | BH7: =IF(Grades!O7="","", Grades!O7) | BI7: =IF(Grades!AA7="","", Grades!AA7) | BJ7: =IF(Grades!AM7="","", Grades!AM7) | BK7: =IF(Grades!AY7="","", Grades!AY7) | BL7: =IF(Grades!AZ7="","", Grades!AZ7) | BM7: =IF(Grades!BA7="","", Grades!BA7) | BN7: =IF(Grades!BB7="","", Grades!BB7) | BO7: =IF(Grades!BC7="","", Grades!BC7) | BP7: =IF(Grades!BD7="","", Grades!BD7) | BQ7: =IF(Grades!BE7="","", Grades!BE7) | BR7: =IF(Grades!BF7="","", Grades!BF7) | BS7: =IF(Grades!BG7="","", Grades!BG7) | BT7: =IF(Grades!BJ7="","", Grades!BJ7) | BU7: =IF(Grades!BK7="","", Grades!BK7) | BV7: =IF(Grades!BL7="","", Grades!BL7)
A8: =IF('Class Info'!A8="","", 'Class Info'!A8) | B8: =IF('Class Info'!B8="","", 'Class Info'!B8) | C8: =IF('Class Info'!C8="","", 'Class Info'!C8) | D8: =IF('Class Info'!D8="","", 'Class Info'!D8) | E8: =IF('Class Info'!E8="","", 'Class Info'!E8) | F8: =IF('Class Info'!F8="","", 'Class Info'!F8) | G8: =IF('Class Info'!G8="","", 'Class Info'!G8) | H8: =IF('Class Info'!H8="","", 'Class Info'!H8) | ... O8: =IF('Class Info'!O8="","", 'Class Info'!O8) | P8: =IF(Grades!D8="","", Grades!D8) | Q8: =IF(Grades!P8="","", Grades!P8) | R8: =IF(Grades!AB8="","", Grades!AB8) | S8: =IF(Grades!AN8="","", Grades!AN8) | T8: =IF(Grades!E8="","", Grades!E8) | U8: =IF(Grades!Q8="","", Grades!Q8) | V8: =IF(Grades!AC8="","", Grades!AC8) | W8: =IF(Grades!AO8="","", Grades!AO8) | X8: =IF(Grades!F8="","", Grades!F8) | Y8: =IF(Grades!R8="","", Grades!R8) | Z8: =IF(Grades!AD8="","", Grades!AD8) | AA8: =IF(Grades!AP8="","", Grades!AP8) | AB8: =IF(Grades!G8="","", Grades!G8) | AC8: =IF(Grades!S8="","", Grades!S8) | AD8: =IF(Grades!AE8="","", Grades!AE8) | AE8: =IF(Grades!AQ8="","", Grades!AQ8) | AF8: =IF(Grades!H8="","", Grades!H8) | AG8: =IF(Grades!T8="","", Grades!T8) | AH8: =IF(Grades!AF8="","", Grades!AF8) | AI8: =IF(Grades!AR8="","", Grades!AR8) | AJ8: =IF(Grades!I8="","", Grades!I8) | AK8: =IF(Grades!U8="","", Grades!U8) | AL8: =IF(Grades!AG8="","", Grades!AG8) | AM8: =IF(Grades!AS8="","", Grades!AS8) | AN8: =IF(Grades!J8="","", Grades!J8) | AO8: =IF(Grades!V8="","", Grades!V8) | AP8: =IF(Grades!AH8="","", Grades!AH8) | AQ8: =IF(Grades!AT8="","", Grades!AT8) | AR8: =IF(Grades!K8="","", Grades!K8) | AS8: =IF(Grades!W8="","", Grades!W8) | AT8: =IF(Grades!AI8="","", Grades!AI8) | AU8: =IF(Grades!AU8="","", Grades!AU8) | AV8: =IF(Grades!L8="","", Grades!L8) | AW8: =IF(Grades!X8="","", Grades!X8) | AX8: =IF(Grades!AJ8="","", Grades!AJ8) | AY8: =IF(Grades!AV8="","", Grades!AV8) | AZ8: =IF(Grades!M8="","", Grades!M8) | BA8: =IF(Grades!Y8="","", Grades!Y8) | BB8: =IF(Grades!AK8="","", Grades!AK8) | BC8: =IF(Grades!AW8="","", Grades!AW8) | BD8: =IF(Grades!N8="","", Grades!N8) | BE8: =IF(Grades!Z8="","", Grades!Z8) | BF8: =IF(Grades!AL8="","", Grades!AL8) | BG8: =IF(Grades!AX8="","", Grades!AX8) | BH8: =IF(Grades!O8="","", Grades!O8) | BI8: =IF(Grades!AA8="","", Grades!AA8) | BJ8: =IF(Grades!AM8="","", Grades!AM8) | BK8: =IF(Grades!AY8="","", Grades!AY8) | BL8: =IF(Grades!AZ8="","", Grades!AZ8) | BM8: =IF(Grades!BA8="","", Grades!BA8) | BN8: =IF(Grades!BB8="","", Grades!BB8) | BO8: =IF(Grades!BC8="","", Grades!BC8) | BP8: =IF(Grades!BD8="","", Grades!BD8) | BQ8: =IF(Grades!BE8="","", Grades!BE8) | BR8: =IF(Grades!BF8="","", Grades!BF8) | BS8: =IF(Grades!BG8="","", Grades!BG8) | BT8: =IF(Grades!BJ8="","", Grades!BJ8) | BU8: =IF(Grades!BK8="","", Grades!BK8) | BV8: =IF(Grades!BL8="","", Grades!BL8)
A9: =IF('Class Info'!A9="","", 'Class Info'!A9) | B9: =IF('Class Info'!B9="","", 'Class Info'!B9) | C9: =IF('Class Info'!C9="","", 'Class Info'!C9) | D9: =IF('Class Info'!D9="","", 'Class Info'!D9) | E9: =IF('Class Info'!E9="","", 'Class Info'!E9) | F9: =IF('Class Info'!F9="","", 'Class Info'!F9) | G9: =IF('Class Info'!G9="","", 'Class Info'!G9) | H9: =IF('Class Info'!H9="","", 'Class Info'!H9) | ... O9: =IF('Class Info'!O9="","", 'Class Info'!O9) | P9: =IF(Grades!D9="","", Grades!D9) | Q9: =IF(Grades!P9="","", Grades!P9) | R9: =IF(Grades!AB9="","", Grades!AB9) | S9: =IF(Grades!AN9="","", Grades!AN9) | T9: =IF(Grades!E9="","", Grades!E9) | U9: =IF(Grades!Q9="","", Grades!Q9) | V9: =IF(Grades!AC9="","", Grades!AC9) | W9: =IF(Grades!AO9="","", Grades!AO9) | X9: =IF(Grades!F9="","", Grades!F9) | Y9: =IF(Grades!R9="","", Grades!R9) | Z9: =IF(Grades!AD9="","", Grades!AD9) | AA9: =IF(Grades!AP9="","", Grades!AP9) | AB9: =IF(Grades!G9="","", Grades!G9) | AC9: =IF(Grades!S9="","", Grades!S9) | AD9: =IF(Grades!AE9="","", Grades!AE9) | AE9: =IF(Grades!AQ9="","", Grades!AQ9) | AF9: =IF(Grades!H9="","", Grades!H9) | AG9: =IF(Grades!T9="","", Grades!T9) | AH9: =IF(Grades!AF9="","", Grades!AF9) | AI9: =IF(Grades!AR9="","", Grades!AR9) | AJ9: =IF(Grades!I9="","", Grades!I9) | AK9: =IF(Grades!U9="","", Grades!U9) | AL9: =IF(Grades!AG9="","", Grades!AG9) | AM9: =IF(Grades!AS9="","", Grades!AS9) | AN9: =IF(Grades!J9="","", Grades!J9) | AO9: =IF(Grades!V9="","", Grades!V9) | AP9: =IF(Grades!AH9="","", Grades!AH9) | AQ9: =IF(Grades!AT9="","", Grades!AT9) | AR9: =IF(Grades!K9="","", Grades!K9) | AS9: =IF(Grades!W9="","", Grades!W9) | AT9: =IF(Grades!AI9="","", Grades!AI9) | AU9: =IF(Grades!AU9="","", Grades!AU9) | AV9: =IF(Grades!L9="","", Grades!L9) | AW9: =IF(Grades!X9="","", Grades!X9) | AX9: =IF(Grades!AJ9="","", Grades!AJ9) | AY9: =IF(Grades!AV9="","", Grades!AV9) | AZ9: =IF(Grades!M9="","", Grades!M9) | BA9: =IF(Grades!Y9="","", Grades!Y9) | BB9: =IF(Grades!AK9="","", Grades!AK9) | BC9: =IF(Grades!AW9="","", Grades!AW9) | BD9: =IF(Grades!N9="","", Grades!N9) | BE9: =IF(Grades!Z9="","", Grades!Z9) | BF9: =IF(Grades!AL9="","", Grades!AL9) | BG9: =IF(Grades!AX9="","", Grades!AX9) | BH9: =IF(Grades!O9="","", Grades!O9) | BI9: =IF(Grades!AA9="","", Grades!AA9) | BJ9: =IF(Grades!AM9="","", Grades!AM9) | BK9: =IF(Grades!AY9="","", Grades!AY9) | BL9: =IF(Grades!AZ9="","", Grades!AZ9) | BM9: =IF(Grades!BA9="","", Grades!BA9) | BN9: =IF(Grades!BB9="","", Grades!BB9) | BO9: =IF(Grades!BC9="","", Grades!BC9) | BP9: =IF(Grades!BD9="","", Grades!BD9) | BQ9: =IF(Grades!BE9="","", Grades!BE9) | BR9: =IF(Grades!BF9="","", Grades!BF9) | BS9: =IF(Grades!BG9="","", Grades!BG9) | BT9: =IF(Grades!BJ9="","", Grades!BJ9) | BU9: =IF(Grades!BK9="","", Grades!BK9) | BV9: =IF(Grades!BL9="","", Grades!BL9)
A10: =IF('Class Info'!A10="","", 'Class Info'!A10) | B10: =IF('Class Info'!B10="","", 'Class Info'!B10) | C10: =IF('Class Info'!C10="","", 'Class Info'!C10) | D10: =IF('Class Info'!D10="","", 'Class Info'!D10) | E10: =IF('Class Info'!E10="","", 'Class Info'!E10) | F10: =IF('Class Info'!F10="","", 'Class Info'!F10) | G10: =IF('Class Info'!G10="","", 'Class Info'!G10) | H10: =IF('Class Info'!H10="","", 'Class Info'!H10) | ... O10: =IF('Class Info'!O10="","", 'Class Info'!O10) | P10: =IF(Grades!D10="","", Grades!D10) | Q10: =IF(Grades!P10="","", Grades!P10) | R10: =IF(Grades!AB10="","", Grades!AB10) | S10: =IF(Grades!AN10="","", Grades!AN10) | T10: =IF(Grades!E10="","", Grades!E10) | U10: =IF(Grades!Q10="","", Grades!Q10) | V10: =IF(Grades!AC10="","", Grades!AC10) | W10: =IF(Grades!AO10="","", Grades!AO10) | X10: =IF(Grades!F10="","", Grades!F10) | Y10: =IF(Grades!R10="","", Grades!R10) | Z10: =IF(Grades!AD10="","", Grades!AD10) | AA10: =IF(Grades!AP10="","", Grades!AP10) | AB10: =IF(Grades!G10="","", Grades!G10) | AC10: =IF(Grades!S10="","", Grades!S10) | AD10: =IF(Grades!AE10="","", Grades!AE10) | AE10: =IF(Grades!AQ10="","", Grades!AQ10) | AF10: =IF(Grades!H10="","", Grades!H10) | AG10: =IF(Grades!T10="","", Grades!T10) | AH10: =IF(Grades!AF10="","", Grades!AF10) | AI10: =IF(Grades!AR10="","", Grades!AR10) | AJ10: =IF(Grades!I10="","", Grades!I10) | AK10: =IF(Grades!U10="","", Grades!U10) | AL10: =IF(Grades!AG10="","", Grades!AG10) | AM10: =IF(Grades!AS10="","", Grades!AS10) | AN10: =IF(Grades!J10="","", Grades!J10) | AO10: =IF(Grades!V10="","", Grades!V10) | AP10: =IF(Grades!AH10="","", Grades!AH10) | AQ10: =IF(Grades!AT10="","", Grades!AT10) | AR10: =IF(Grades!K10="","", Grades!K10) | AS10: =IF(Grades!W10="","", Grades!W10) | AT10: =IF(Grades!AI10="","", Grades!AI10) | AU10: =IF(Grades!AU10="","", Grades!AU10) | AV10: =IF(Grades!L10="","", Grades!L10) | AW10: =IF(Grades!X10="","", Grades!X10) | AX10: =IF(Grades!AJ10="","", Grades!AJ10) | AY10: =IF(Grades!AV10="","", Grades!AV10) | AZ10: =IF(Grades!M10="","", Grades!M10) | BA10: =IF(Grades!Y10="","", Grades!Y10) | BB10: =IF(Grades!AK10="","", Grades!AK10) | BC10: =IF(Grades!AW10="","", Grades!AW10) | BD10: =IF(Grades!N10="","", Grades!N10) | BE10: =IF(Grades!Z10="","", Grades!Z10) | BF10: =IF(Grades!AL10="","", Grades!AL10) | BG10: =IF(Grades!AX10="","", Grades!AX10) | BH10: =IF(Grades!O10="","", Grades!O10) | BI10: =IF(Grades!AA10="","", Grades!AA10) | BJ10: =IF(Grades!AM10="","", Grades!AM10) | BK10: =IF(Grades!AY10="","", Grades!AY10) | BL10: =IF(Grades!AZ10="","", Grades!AZ10) | BM10: =IF(Grades!BA10="","", Grades!BA10) | BN10: =IF(Grades!BB10="","", Grades!BB10) | BO10: =IF(Grades!BC10="","", Grades!BC10) | BP10: =IF(Grades!BD10="","", Grades!BD10) | BQ10: =IF(Grades!BE10="","", Grades!BE10) | BR10: =IF(Grades!BF10="","", Grades!BF10) | BS10: =IF(Grades!BG10="","", Grades!BG10) | BT10: =IF(Grades!BJ10="","", Grades!BJ10) | BU10: =IF(Grades!BK10="","", Grades!BK10) | BV10: =IF(Grades!BL10="","", Grades!BL10)
A11: =IF('Class Info'!A11="","", 'Class Info'!A11) | B11: =IF('Class Info'!B11="","", 'Class Info'!B11) | C11: =IF('Class Info'!C11="","", 'Class Info'!C11) | D11: =IF('Class Info'!D11="","", 'Class Info'!D11) | E11: =IF('Class Info'!E11="","", 'Class Info'!E11) | F11: =IF('Class Info'!F11="","", 'Class Info'!F11) | G11: =IF('Class Info'!G11="","", 'Class Info'!G11) | H11: =IF('Class Info'!H11="","", 'Class Info'!H11) | ... O11: =IF('Class Info'!O11="","", 'Class Info'!O11) | P11: =IF(Grades!D11="","", Grades!D11) | Q11: =IF(Grades!P11="","", Grades!P11) | R11: =IF(Grades!AB11="","", Grades!AB11) | S11: =IF(Grades!AN11="","", Grades!AN11) | T11: =IF(Grades!E11="","", Grades!E11) | U11: =IF(Grades!Q11="","", Grades!Q11) | V11: =IF(Grades!AC11="","", Grades!AC11) | W11: =IF(Grades!AO11="","", Grades!AO11) | X11: =IF(Grades!F11="","", Grades!F11) | Y11: =IF(Grades!R11="","", Grades!R11) | Z11: =IF(Grades!AD11="","", Grades!AD11) | AA11: =IF(Grades!AP11="","", Grades!AP11) | AB11: =IF(Grades!G11="","", Grades!G11) | AC11: =IF(Grades!S11="","", Grades!S11) | AD11: =IF(Grades!AE11="","", Grades!AE11) | AE11: =IF(Grades!AQ11="","", Grades!AQ11) | AF11: =IF(Grades!H11="","", Grades!H11) | AG11: =IF(Grades!T11="","", Grades!T11) | AH11: =IF(Grades!AF11="","", Grades!AF11) | AI11: =IF(Grades!AR11="","", Grades!AR11) | AJ11: =IF(Grades!I11="","", Grades!I11) | AK11: =IF(Grades!U11="","", Grades!U11) | AL11: =IF(Grades!AG11="","", Grades!AG11) | AM11: =IF(Grades!AS11="","", Grades!AS11) | AN11: =IF(Grades!J11="","", Grades!J11) | AO11: =IF(Grades!V11="","", Grades!V11) | AP11: =IF(Grades!AH11="","", Grades!AH11) | AQ11: =IF(Grades!AT11="","", Grades!AT11) | AR11: =IF(Grades!K11="","", Grades!K11) | AS11: =IF(Grades!W11="","", Grades!W11) | AT11: =IF(Grades!AI11="","", Grades!AI11) | AU11: =IF(Grades!AU11="","", Grades!AU11) | AV11: =IF(Grades!L11="","", Grades!L11) | AW11: =IF(Grades!X11="","", Grades!X11) | AX11: =IF(Grades!AJ11="","", Grades!AJ11) | AY11: =IF(Grades!AV11="","", Grades!AV11) | AZ11: =IF(Grades!M11="","", Grades!M11) | BA11: =IF(Grades!Y11="","", Grades!Y11) | BB11: =IF(Grades!AK11="","", Grades!AK11) | BC11: =IF(Grades!AW11="","", Grades!AW11) | BD11: =IF(Grades!N11="","", Grades!N11) | BE11: =IF(Grades!Z11="","", Grades!Z11) | BF11: =IF(Grades!AL11="","", Grades!AL11) | BG11: =IF(Grades!AX11="","", Grades!AX11) | BH11: =IF(Grades!O11="","", Grades!O11) | BI11: =IF(Grades!AA11="","", Grades!AA11) | BJ11: =IF(Grades!AM11="","", Grades!AM11) | BK11: =IF(Grades!AY11="","", Grades!AY11) | BL11: =IF(Grades!AZ11="","", Grades!AZ11) | BM11: =IF(Grades!BA11="","", Grades!BA11) | BN11: =IF(Grades!BB11="","", Grades!BB11) | BO11: =IF(Grades!BC11="","", Grades!BC11) | BP11: =IF(Grades!BD11="","", Grades!BD11) | BQ11: =IF(Grades!BE11="","", Grades!BE11) | BR11: =IF(Grades!BF11="","", Grades!BF11) | BS11: =IF(Grades!BG11="","", Grades!BG11) | BT11: =IF(Grades!BJ11="","", Grades!BJ11) | BU11: =IF(Grades!BK11="","", Grades!BK11) | BV11: =IF(Grades!BL11="","", Grades!BL11)
